Workbook

Sheet Resumo
A1: Nº | B1: Menu principal | C1: Pacote | D1: Submenus (documento) | E1: Acréscimos | F1: Retirados | G1: Total atual | H1: Listados | I1: Conferência
A2: 1 | B2: Dashboard Financeiro | C2: 01 — Fundação | D2: 7 | E2: =COUNTIFS(Submenus!$B:$B,B2,Submenus!$E:$E,"Acréscimo") -> 0 | F2: 0 | G2: =D2+E2-F2 -> 7 | H2: =COUNTIF(Submenus!$B:$B,B2) -> 7 | I2: =IF(G2=H2,"OK","DIVERGENTE") -> OK
A3: 2 | B3: Gestão de Recebimentos | C3: 01 — Fundação | D3: 8 | E3: =COUNTIFS(Submenus!$B:$B,B3,Submenus!$E:$E,"Acréscimo") -> 0 | F3: 0 | G3: =D3+E3-F3 -> 8 | H3: =COUNTIF(Submenus!$B:$B,B3) -> 8 | I3: =IF(G3=H3,"OK","DIVERGENTE") -> OK
A4: 3 | B4: Contas a Pagar | C4: 01 — Fundação | D4: 8 | E4: =COUNTIFS(Submenus!$B:$B,B4,Submenus!$E:$E,"Acréscimo") -> 0 | F4: 0 | G4: =D4+E4-F4 -> 8 | H4: =COUNTIF(Submenus!$B:$B,B4) -> 8 | I4: =IF(G4=H4,"OK","DIVERGENTE") -> OK
A5: 4 | B5: Tesouraria e Bancos | C5: 02 — Operações | D5: 9 | E5: =COUNTIFS(Submenus!$B:$B,B5,Submenus!$E:$E,"Acréscimo") -> 3 | F5: 0 | G5: =D5+E5-F5 -> 12 | H5: =COUNTIF(Submenus!$B:$B,B5) -> 12 | I5: =IF(G5=H5,"OK","DIVERGENTE") -> OK
A6: 5 | B6: Saldos e Contas Correntes | C6: 01 — Fundação | D6: 8 | E6: =COUNTIFS(Submenus!$B:$B,B6,Submenus!$E:$E,"Acréscimo") -> 3 | F6: 0 | G6: =D6+E6-F6 -> 11 | H6: =COUNTIF(Submenus!$B:$B,B6) -> 11 | I6: =IF(G6=H6,"OK","DIVERGENTE") -> OK
A7: 6 | B7: Repasses e Antecipações | C7: 02 — Operações | D7: 10 | E7: =COUNTIFS(Submenus!$B:$B,B7,Submenus!$E:$E,"Acréscimo") -> 3 | F7: 0 | G7: =D7+E7-F7 -> 13 | H7: =COUNTIF(Submenus!$B:$B,B7) -> 13 | I7: =IF(G7=H7,"OK","DIVERGENTE") -> OK
A8: 7 | B8: Gateways e Meios de Pagamento | C8: 02 — Operações | D8: 10 | E8: =COUNTIFS(Submenus!$B:$B,B8,Submenus!$E:$E,"Acréscimo") -> 0 | F8: 0 | G8: =D8+E8-F8 -> 10 | H8: =COUNTIF(Submenus!$B:$B,B8) -> 10 | I8: =IF(G8=H8,"OK","DIVERGENTE") -> OK
A9: 8 | B9: Divisão de Receitas e Taxas | C9: 02 — Operações | D9: 9 | E9: =COUNTIFS(Submenus!$B:$B,B9,Submenus!$E:$E,"Acréscimo") -> 4 | F9: 0 | G9: =D9+E9-F9 -> 13 | H9: =COUNTIF(Submenus!$B:$B,B9) -> 13 | I9: =IF(G9=H9,"OK","DIVERGENTE") -> OK
A10: 9 | B10: Conciliação Financeira | C10: 03 — Controle | D10: 10 | E10: =COUNTIFS(Submenus!$B:$B,B10,Submenus!$E:$E,"Acréscimo") -> 0 | F10: 0 | G10: =D10+E10-F10 -> 10 | H10: =COUNTIF(Submenus!$B:$B,B10) -> 10 | I10: =IF(G10=H10,"OK","DIVERGENTE") -> OK
A11: 10 | B11: Estornos, Chargebacks e Riscos | C11: 03 — Controle | D11: 9 | E11: =COUNTIFS(Submenus!$B:$B,B11,Submenus!$E:$E,"Acréscimo") -> 3 | F11: 0 | G11: =D11+E11-F11 -> 12 | H11: =COUNTIF(Submenus!$B:$B,B11) -> 12 | I11: =IF(G11=H11,"OK","DIVERGENTE") -> OK
A12: 11 | B12: Planejamento Financeiro | C12: 03 — Controle | D12: 9 | E12: =COUNTIFS(Submenus!$B:$B,B12,Submenus!$E:$E,"Acréscimo") -> 0 | F12: 0 | G12: =D12+E12-F12 -> 9 | H12: =COUNTIF(Submenus!$B:$B,B12) -> 9 | I12: =IF(G12=H12,"OK","DIVERGENTE") -> OK
A13: 12 | B13: Gestão de Contratos | C13: 03 — Controle | D13: 8 | E13: =COUNTIFS(Submenus!$B:$B,B13,Submenus!$E:$E,"Acréscimo") -> 0 | F13: 0 | G13: =D13+E13-F13 -> 8 | H13: =COUNTIF(Submenus!$B:$B,B13) -> 8 | I13: =IF(G13=H13,"OK","DIVERGENTE") -> OK
... A18: 17 | B18: Configurações Financeiras | C18: 04 — Inteligência e Governança | D18: 10 | E18: =COUNTIFS(Submenus!$B:$B,B18,Submenus!$E:$E,"Acréscimo") -> 0 | F18: 0 | G18: =D18+E18-F18 -> 10 | H18: =COUNTIF(Submenus!$B:$B,B18) -> 10 | I18: =IF(G18=H18,"OK","DIVERGENTE") -> OK
B19: Total | D19: =SUM(D2:D18) -> 154 | E19: =SUM(E2:E18) -> 19 | F19: =SUM(F2:F18) -> 1 | G19: =SUM(G2:G18) -> 172 | H19: =SUM(H2:H18) -> 172 | I19: =IF(AND(D19=154,G19=H19),"OK","DIVERGENTE") -> OK
B21: Notas: colunas D e F (azul) são entradas. D = contagem do documento original (154). Acréscimos = itens novos sugeridos. Retirado = Permissões e Perfis em Auditoria (duplicidade).

Sheet Submenus
A1: Código | B1: Menu principal | C1: Submenu | D1: Pacote | E1: Origem | F1: Observação
A2: 01.01 | B2: Dashboard Financeiro | C2: Visão Geral Financeira | D2: 01 — Fundação | E2: Documento
A3: 01.02 | B3: Dashboard Financeiro | C3: Indicadores de Receitas e Despesas | D3: 01 — Fundação | E3: Documento
A4: 01.03 | B4: Dashboard Financeiro | C4: Posição de Caixa e Bancos | D4: 01 — Fundação | E4: Documento
A5: 01.04 | B5: Dashboard Financeiro | C5: Saldos Consolidados | D5: 01 — Fundação | E5: Documento
A6: 01.05 | B6: Dashboard Financeiro | C6: Previsão de Fluxo de Caixa | D6: 01 — Fundação | E6: Documento
A7: 01.06 | B7: Dashboard Financeiro | C7: Alertas e Pendências | D7: 01 — Fundação | E7: Documento
A8: 01.07 | B8: Dashboard Financeiro | C8: Painel Executivo | D8: 01 — Fundação | E8: Documento
A9: 02.01 | B9: Gestão de Recebimentos | C9: Contas a Receber | D9: 01 — Fundação | E9: Documento
A10: 02.02 | B10: Gestão de Recebimentos | C10: Recebimentos por Período | D10: 01 — Fundação | E10: Documento
A11: 02.03 | B11: Gestão de Recebimentos | C11: Recebimentos por Cliente | D11: 01 — Fundação | E11: Documento
A12: 02.04 | B12: Gestão de Recebimentos | C12: Vendas e Transações | D12: 01 — Fundação | E12: Documento
A13: 02.05 | B13: Gestão de Recebimentos | C13: Agenda de Recebíveis | D13: 01 — Fundação | E13: Documento
... A16: 02.08 | B16: Gestão de Recebimentos | C16: Histórico de Recebimentos | D16: 01 — Fundação | E16: Documento
A17: 03.01 | B17: Contas a Pagar | C17: Contas a Pagar em Aberto | D17: 01 — Fundação | E17: Proposta | F17: Renomeado (antes: Contas a Pagar)
A18: 03.02 | B18: Contas a Pagar | C18: Lançamento de Despesas | D18: 01 — Fundação | E18: Proposta
A19: 03.03 | B19: Contas a Pagar | C19: Agenda de Pagamentos | D19: 01 — Fundação | E19: Proposta
A20: 03.04 | B20: Contas a Pagar | C20: Pagamentos por Fornecedor | D20: 01 — Fundação | E20: Proposta
A21: 03.05 | B21: Contas a Pagar | C21: Pagamentos em Lote | D21: 01 — Fundação | E21: Proposta
A22: 03.06 | B22: Contas a Pagar | C22: Despesas Recorrentes | D22: 01 — Fundação | E22: Proposta
A23: 03.07 | B23: Contas a Pagar | C23: Cadastro de Fornecedores | D23: 01 — Fundação | E23: Proposta
A24: 03.08 | B24: Contas a Pagar | C24: Histórico de Pagamentos | D24: 01 — Fundação | E24: Proposta
A25: 04.01 | B25: Tesouraria e Bancos | C25: Dashboard de Tesouraria | D25: 02 — Operações | E25: Documento
A26: 04.02 | B26: Tesouraria e Bancos | C26: Contas Bancárias | D26: 02 — Operações | E26: Documento
A27: 04.03 | B27: Tesouraria e Bancos | C27: Saldos e Extratos | D27: 02 — Operações | E27: Documento
A28: 04.04 | B28: Tesouraria e Bancos | C28: Movimentações Financeiras | D28: 02 — Operações | E28: Documento
A29: 04.05 | B29: Tesouraria e Bancos | C29: Transferências Bancárias | D29: 02 — Operações | E29: Documento
... A154: 15.08 | B154: Aprovações Financeiras | C154: Histórico de Aprovações | D154: 02 — Operações | E154: Proposta
A155: 16.01 | B155: Auditoria e Governança | C155: Log de Atividades | D155: 04 — Inteligência e Governança | E155: Proposta | F155: Removido: Permissões e Perfis (mantido em 17 – Configurações)
A156: 16.02 | B156: Auditoria e Governança | C156: Trilha de Auditoria Financeira | D156: 04 — Inteligência e Governança | E156: Proposta
A157: 16.03 | B157: Auditoria e Governança | C157: Histórico de Alterações | D157: 04 — Inteligência e Governança | E157: Proposta
A158: 16.04 | B158: Auditoria e Governança | C158: Acessos e Sessões | D158: 04 — Inteligência e Governança | E158: Proposta
A159: 16.05 | B159: Auditoria e Governança | C159: Evidências e Anexos | D159: 04 — Inteligência e Governança | E159: Proposta
A160: 16.06 | B160: Auditoria e Governança | C160: Alertas de Anomalias | D160: 04 — Inteligência e Governança | E160: Proposta
A161: 16.07 | B161: Auditoria e Governança | C161: Revisão de Acessos | D161: 04 — Inteligência e Governança | E161: Proposta
A162: 16.08 | B162: Auditoria e Governança | C162: Políticas de Conformidade | D162: 04 — Inteligência e Governança | E162: Proposta
A163: 16.09 | B163: Auditoria e Governança | C163: Relatórios de Auditoria | D163: 04 — Inteligência e Governança | E163: Proposta
A164: 17.01 | B164: Configurações Financeiras | C164: Parâmetros Gerais | D164: 04 — Inteligência e Governança | E164: Proposta
A165: 17.02 | B165: Configurações Financeiras | C165: Contas e Bancos Padrão | D165: 04 — Inteligência e Governança | E165: Proposta
A166: 17.03 | B166: Configurações Financeiras | C166: Categorias Financeiras | D166: 04 — Inteligência e Governança | E166: Proposta
...

Sheet Pacotes
A1: Pacote | B1: Escopo | C1: Menus incluídos
A2: 01 — Fundação | B2: Dashboard, núcleo financeiro, contas, recebimentos, pagamentos, saldos (incluindo cadastro bancário do produtor) e permissões | C2: 01, 02, 03, 05
A3: 02 — Operações | B3: Tesouraria (incluindo PDV), gateways, taxas e promoções, repasses, acerto de evento, antecipações, aprovações e assinaturas | C3: 04, 06, 07, 08, 15
A4: 03 — Controle | B4: Conciliações, estornos, cancelamento de evento, chargebacks, contratos, planejamento e integração contábil/fiscal | C4: 09, 10, 11, 12, 13
A5: 04 — Inteligência e Governança | B5: Relatórios, indicadores, auditoria, logs, automações e configurações | C5: 14, 16, 17
A7: Observação: o documento não mapeia menus a pacotes; a distribuição é uma sugestão a partir do escopo descrito.

Sheet Perfis
A1: Perfil | B1: Visão e acesso
A2: Administrador | B2: Todos os menus, gestão de permissões e auditoria
A3: Financeiro interno | B3: Visão consolidada, repasses, recebimentos, taxas, aprovações e relatórios
A4: Tesouraria | B4: Bancos, caixa, conciliações e pagamentos autorizados
A5: Contabilidade | B5: Classificações, fechamento, demonstrativos e integração fiscal
A6: Produtor ou parceiro | B6: Apenas seus saldos, solicitações, demonstrativos e operações autorizadas
A7: Auditor | B7: Consulta de históricos, operações, evidências e logs, sem execução financeira

Sheet Regras de Arquitetura
A1: Regra | B1: Descrição | C1: Menus relacionados
A2: Razão de dupla entrada, imutável | B2: Todo lançamento tem débito e crédito. Erros são corrigidos por lançamento reverso, nunca por edição ou exclusão. | C2: 05, 09, 13, 16
A3: Idempotência | B3: Webhooks, cobranças e repasses usam chave única para que o mesmo evento não seja processado duas vezes. | C3: 06, 07, 09
A4: Segregação de funções | B4: Quem cria um repasse, pagamento ou antecipação não pode aprová-lo nem executá-lo. | C4: 15, 16, 17
A5: Segurança em operações sensíveis | B5: Autenticação em dois fatores para repasses e trava temporária de saques após troca de conta bancária. | C5: 05, 06, 16
A6: Fechamento de período | B6: Após o fechamento, lançamentos em meses encerrados ficam bloqueados; correções entram no período aberto. | C6: 13, 17
A7: Saldo ligado ao status do evento | B7: O saldo só é liberado conforme a regra do evento (por exemplo, após sua realização), com reserva de garantia quando aplicável. | C7: 05, 06, 10
A8: Separação receita x recursos de terceiros | B8: Distinguir faturamento, valores recebidos, valores a repassar, taxas e receita própria. Saldo bancário não é lucro. | C8: 05, 08, 14
A9: Permissões também nas APIs | B9: Restrições por perfil valem nas telas, nas APIs e nas consultas de dados. | C9: 16, 17
